<?xml version="1.0" encoding="utf-8"?>
<!-- This URDF was automatically created by SolidWorks to URDF Exporter! Originally created by Stephen Brawner (brawner@gmail.com) 
  and edited by Valrob (inspired by turtlebot3)
     Commit Version: 1.6.0-1-g15f4949  Build Version: 1.6.7594.29634
     For more information, please see http://wiki.ros.org/sw_urdf_exporter -->
<robot name="valrob_description" xmlns:xacro="http://ros.org/wiki/xacro">
  <xacro:include filename="$(find valrob_description)/urdf/common_properties.xacro"/>
  <xacro:include filename="$(find valrob_description)/urdf/valrob_description.gazebo.xacro"/>

  <link name="base_footprint"/>

  <joint name="base_joint" type="fixed">
    <parent link="base_footprint"/>
    <child link="base_link"/>
    <origin xyz="0.0 0.0 0.010" rpy="0 0 0"/>
  </joint>

  <!-- base link -->
  <link name="base_link">
    <inertial>
      <origin
        xyz="-0.027491 1.0825E-15 0.20899"
        rpy="0 0 0" />
      <mass value="1.3465" />
      <inertia
        ixx="0.039404"
        ixy="-1.7092E-17"
        ixz="-0.00031636"
        iyy="0.034752"
        iyz="-1.0563E-19"
        izz="0.013857" />
    </inertial>
    <visual>
      <origin xyz="0 0 0" rpy="0 0 0"/>
      <geometry>
        <mesh filename="package://valrob_description/meshes/base_link.STL" />
      </geometry>
      <material name="grey" />
        
    </visual>
    <collision>
      <origin xyz="0 0 0" rpy="0 0 0" />
      <geometry>
        <mesh filename="package://valrob_description/meshes/base_link.STL" />
      </geometry>
    </collision>
  </link>

  <!-- right wheel -->
  <link name="right_wheel">
    <inertial>
      <origin
        xyz="-8.8818E-16 1.1935E-15 0.013932"
        rpy="0 0 0" />
      <mass value="0.025932" />
      <inertia
        ixx="6.7434E-06"
        ixy="-1.2105E-37"
        ixz="2.5269E-22"
        iyy="6.7434E-06"
        iyz="0"
        izz="1.3177E-05" />
    </inertial>
    <visual>
      <origin xyz="0 0 0" rpy="0 0 0" />
      <geometry>
        <mesh filename="package://valrob_description/meshes/right_wheel.STL" />
      </geometry>
      <material name="red"/>
    </visual>
    <collision>
      <origin xyz="0 0 0" rpy="0 0 0" />
      <geometry>
        <mesh filename="package://valrob_description/meshes/right_wheel.STL" />
      </geometry>
    </collision>
  </link>

  <!-- right wheel       joint -->
  <joint name="right_wheel_joint" type="continuous">
    <origin xyz="0 -0.132 0.032" rpy="-1.5708 0 3.1416" />
    <parent link="base_link" />
    <child link="right_wheel" />
    <axis xyz="0 0 1" />
  </joint>


  <!-- left wheel -->
  <link name="left_wheel">
    <inertial>
      <origin
        xyz="-4.85722573273506E-17 0 0.00626572239693311"
        rpy="0 0 0" />
      <mass value="0.025932276559057" />
      <inertia
        ixx="6.74338252769793E-06"
        ixy="-4.23516473627121E-22"
        ixz="-1.29745545514423E-20"
        iyy="6.74338252769793E-06"
        iyz="-2.24665558815487E-22"
        izz="1.31774082256374E-05" />
    </inertial>
    <visual>
      <origin xyz="0 0 0" rpy="0 0 0" />
      <geometry>
        <mesh filename="package://valrob_description/meshes/left_wheel.STL" />
      </geometry>
      <material name="red"/>
        
    </visual>
    <collision>
      <origin xyz="0 0 0" rpy="0 0 0" />
      <geometry>
        <mesh filename="package://valrob_description/meshes/left_wheel.STL" />
      </geometry>
    </collision>
  </link>

   <!-- left wheel       joint -->
  <joint name="left_wheel_joint" type="continuous">
    <origin xyz="0 0.13967 0.032" rpy="-1.5708 -1.2033 0" />
    <parent link="base_link" />
    <child link="left_wheel" />
    <axis xyz="0 0 1" />
  </joint>

  <!-- laser -->
  <link name="laser">
    <inertial>
      <origin
        xyz="0 0 0.015"
        rpy="0 0 0" />
      <mass value="0.19085175370558" />
      <inertia
        ixx="0.000110932581841368"
        ixy="-2.48950075531325E-37"
        ixz="0"
        iyy="0.0001932374006269"
        iyz="0"
        izz="0.000110932581841368" />
    </inertial>
    <visual>
      <origin xyz="0 0 0" rpy="1.57 0 0" />
      <geometry>
        <mesh filename="package://valrob_description/meshes/laser.STL" />
      </geometry>
      <material name="white"/>
    </visual>
    <collision>
      <origin xyz="0 0 0" rpy="1.57 0 0" />
      <geometry>
        <mesh filename="package://valrob_description/meshes/laser.STL" />
      </geometry>
    </collision>
  </link>


   <!-- laser            joint -->
  <joint name="laser_joint" type="fixed">
    <origin
      xyz="0 0 0.388"
      rpy="0 0 0" />
    <parent link="base_link" />
    <child link="laser" />
    <axis xyz="0 0 0" />
  </joint>

  <!-- imu -->
  <link name="imu_link">
    <inertial>
      <origin xyz="0 0 0" rpy="0 0 0" />
      <mass value="0" />
      <inertia
        ixx="0"
        ixy="0"
        ixz="0"
        iyy="0"
        iyz="0"
        izz="0" />
    </inertial>
    <visual>
      <origin xyz="0 0 0" rpy="0 0 0" />
      <geometry>
        <mesh filename="package://valrob_description/meshes/imu.STL" />
      </geometry>
      <material name="">
        <color rgba="1 1 1 1" />
      </material>
    </visual>
    <collision>
      <origin xyz="0 0 0" rpy="0 0 0" />
      <geometry>
        <mesh filename="package://valrob_description/meshes/imu.STL" />
      </geometry>
    </collision>
  </link>

  <!-- imu               joint -->
  <joint name="imu_joint" type="fixed">
    <origin xyz="0.01 -0.01 0.029" rpy="-1.5708 0 3.1416" />
    <parent link="base_link" />
    <child link="imu_link" />
    <axis  xyz="0 0 0" />
  </joint>
</robot>